[2018-09-30 12:52:55 +0000] [7677] [INFO] Starting gunicorn 19.4.5
[2018-09-30 12:52:55 +0000] [7677] [INFO] Listening at: http://127.0.0.1:8000 (7677)
[2018-09-30 12:52:55 +0000] [7677] [INFO] Using worker: sync
[2018-09-30 12:52:55 +0000] [7681] [INFO] Booting worker with pid: 7681
[2018-09-30 12:52:55 +0000] [7681] [ERROR] Exception in worker process:
Traceback (most recent call last):
  File "/usr/lib/python2.7/dist-packages/gunicorn/arbiter.py", line 515, in spawn_worker
    worker.init_process()
  File "/usr/lib/python2.7/dist-packages/gunicorn/workers/base.py", line 122, in init_process
    self.load_wsgi()
  File "/usr/lib/python2.7/dist-packages/gunicorn/workers/base.py", line 130, in load_wsgi
    self.wsgi = self.app.wsgi()
  File "/usr/lib/python2.7/dist-packages/gunicorn/app/base.py", line 67, in wsgi
    self.callable = self.load()
  File "/usr/lib/python2.7/dist-packages/gunicorn/app/wsgiapp.py", line 65, in load
    return self.load_wsgiapp()
  File "/usr/lib/python2.7/dist-packages/gunicorn/app/wsgiapp.py", line 52, in load_wsgiapp
    return util.import_app(self.app_uri)
  File "/usr/lib/python2.7/dist-packages/gunicorn/util.py", line 366, in import_app
    __import__(module)
ImportError: No module named app
Traceback (most recent call last):
  File "/usr/lib/python2.7/dist-packages/gunicorn/arbiter.py", line 515, in spawn_worker
    worker.init_process()
  File "/usr/lib/python2.7/dist-packages/gunicorn/workers/base.py", line 122, in init_process
    self.load_wsgi()
  File "/usr/lib/python2.7/dist-packages/gunicorn/workers/base.py", line 130, in load_wsgi
    self.wsgi = self.app.wsgi()
  File "/usr/lib/python2.7/dist-packages/gunicorn/app/base.py", line 67, in wsgi
    self.callable = self.load()
  File "/usr/lib/python2.7/dist-packages/gunicorn/app/wsgiapp.py", line 65, in load
    return self.load_wsgiapp()
  File "/usr/lib/python2.7/dist-packages/gunicorn/app/wsgiapp.py", line 52, in load_wsgiapp
    return util.import_app(self.app_uri)
  File "/usr/lib/python2.7/dist-packages/gunicorn/util.py", line 366, in import_app
    __import__(module)
ImportError: No module named app
[2018-09-30 12:52:55 +0000] [7681] [INFO] Worker exiting (pid: 7681)
[2018-09-30 12:52:55 +0000] [7677] [INFO] Shutting down: Master
[2018-09-30 12:52:55 +0000] [7677] [INFO] Reason: Worker failed to boot.
